<?xml version="1.0" ?>
<!-- =================================================================================== -->
<!-- |    This document was autogenerated by xacro from sw_v3.xacro                    | -->
<!-- |    EDITING THIS FILE BY HAND IS NOT RECOMMENDED                                 | -->
<!-- =================================================================================== -->
<!-- Revolute-Revolute Manipulator -->
<robot name="sw_v3" xmlns:xacro="http://www.ros.org/wiki/xacro">
  <!-- Link 1 -->
  <!-- ros_control plugin -->
  <gazebo>
    <plugin filename="libgazebo_ros_control.so" name="gazebo_ros_control">
      <robotNamespace>/sw_v3</robotNamespace>
      <robotSimType>gazebo_ros_control/DefaultRobotHWSim</robotSimType>
      <legacyModeNS>true</legacyModeNS>
    </plugin>
  </gazebo>
  <gazebo reference="base_link">
    <mu1>0.2</mu1>
    <mu2>0.2</mu2>
    <material>Gazebo/white</material>
  </gazebo>
  <gazebo reference="link1">
    <mu1>0.2</mu1>
    <mu2>0.2</mu2>
    <material>Gazebo/white</material>
  </gazebo>
  <gazebo reference="link2">
    <mu1>0.2</mu1>
    <mu2>0.2</mu2>
    <material>Gazebo/white</material>
  </gazebo>
  <gazebo reference="link3">
    <mu1>0.2</mu1>
    <mu2>0.2</mu2>
    <material>Gazebo/white</material>
  </gazebo>
  <gazebo reference="link4">
    <mu1>0.2</mu1>
    <mu2>0.2</mu2>
    <material>Gazebo/white</material>
  </gazebo>
  <gazebo reference="link5">
    <mu1>0.2</mu1>
    <mu2>0.2</mu2>
    <material>Gazebo/white</material>
  </gazebo>
  <gazebo reference="link6">
    <mu1>0.2</mu1>
    <mu2>0.2</mu2>
    <material>Gazebo/Black</material>
  </gazebo>
  <material name="black">
    <color rgba="0.0 0.0 0.0 1.0"/>
  </material>
  <material name="blue">
    <color rgba="0.0 0.0 0.8 1.0"/>
  </material>
  <material name="green">
    <color rgba="0.0 0.8 0.0 1.0"/>
  </material>
  <material name="grey">
    <color rgba="0.8 0.8 0.8 1.0"/>
  </material>
  <material name="orange">
    <color rgba="1.0 0.423529411765 0.0392156862745 1.0"/>
  </material>
  <material name="brown">
    <color rgba="0.870588235294 0.811764705882 0.764705882353 1.0"/>
  </material>
  <material name="red">
    <color rgba="0.8 0.0 0.0 1.0"/>
  </material>
  <material name="white">
    <color rgba="1.0 1.0 1.0 1.0"/>
  </material>
  <!-- Used for fixing robot to Gazebo 'base_link' -->
  <link name="world"/>
  <joint name="joint0" type="fixed">
    <parent link="world"/>
    <child link="base_link"/>
  </joint>
  <link name="base_link">
    <inertial>
      <origin rpy="0 0 0" xyz="-0.0046135 -0.00012186 0.096013"/>
      <mass value="5.7694"/>
      <inertia ixx="0.016279" ixy="-2.9241E-06" ixz="-0.00019498" iyy="0.01308" iyz="-1.4038E-05" izz="0.0053116"/>
    </inertial>
    <visual>
      <origin rpy="0 0 0" xyz="0 0 0"/>
      <geometry>
        <mesh filename="package://sw_v3_description/meshes/assem1.STL"/>
      </geometry>
      <material name="grey"/>
    </visual>
    <collision>
      <origin rpy="0 0 0" xyz="0 0 0"/>
      <geometry>
        <mesh filename="package://sw_v3_description/meshes/assem1.STL"/>
      </geometry>
    </collision>
  </link>
  <!-- link1 -->
  <joint name="joint1" type="revolute">
    <origin rpy="0 0 0" xyz="0 0 0.2063"/>
    <parent link="base_link"/>
    <child link="link1"/>
    <axis xyz="0 0 1"/>
    <limit effort="1" lower="-3.1415" upper="3.1415" velocity="1.57079632679"/>
  </joint>
  <link name="link1">
    <inertial>
      <origin rpy="0 0 0" xyz="-0.002448 0.0061877 0.25206"/>
      <mass value="1.2912"/>
      <inertia ixx="0.00050926" ixy="2.3182E-05" ixz="5.5414E-05" iyy="0.00045458" iyz="-0.00014037" izz="7.6348E-05"/>
    </inertial>
    <visual>
      <origin rpy="0 0 0" xyz="0 0 0"/>
      <geometry>
        <mesh filename="package://sw_v3_description/meshes/assem2.STL"/>
      </geometry>
      <material name="grey"/>
    </visual>
    <collision>
      <origin rpy="0 0 0" xyz="0 0 0"/>
      <geometry>
        <mesh filename="package://sw_v3_description/meshes/assem2.STL"/>
      </geometry>
    </collision>
  </link>
  <!-- link2 -->
  <joint name="joint2" type="revolute">
    <origin rpy="-0.22802 0.12977 -0.01488" xyz="-2.5882E-05 -4.4829E-05 0.079795"/>
    <parent link="link1"/>
    <child link="link2"/>
    <axis xyz="0 0 1"/>
    <limit effort="1" lower="-3.1415" upper="3.1415" velocity="1.57079632679"/>
  </joint>
  <link name="link2">
    <inertial>
      <origin rpy="0 0 0" xyz="0.040734 0.037687 0.18694"/>
      <mass value="6.5273"/>
      <inertia ixx="0.020545" ixy="-0.0025461" ixz="-0.0054607" iyy="0.023538" iyz="-0.0063656" izz="0.01031"/>
    </inertial>
    <visual>
      <origin rpy="0 0 0" xyz="0 0 0"/>
      <geometry>
        <mesh filename="package://sw_v3_description/meshes/assem3.STL"/>
      </geometry>
      <material name="grey"/>
    </visual>
    <collision>
      <origin rpy="0 0 0" xyz="0 0 0"/>
      <geometry>
        <mesh filename="package://sw_v3_description/meshes/assem3.STL"/>
      </geometry>
    </collision>
  </link>
  <!-- link3 -->
  <joint name="joint3" type="revolute">
    <origin rpy="-0.13318 0.22606 -2.6331" xyz="-0.031687 -0.054883 0.23651"/>
    <parent link="link2"/>
    <child link="link3"/>
    <axis xyz="0 0 1"/>
    <limit effort="1" lower="-3.1415" upper="3.1415" velocity="1.57079632679"/>
  </joint>
  <link name="link3">
    <inertial>
      <origin rpy="0 0 0" xyz="-0.032134 -0.061684 0.28225"/>
      <mass value="1.2912"/>
      <inertia ixx="0.00049237" ixy="-4.7209E-06" ixz="-7.3968E-05" iyy="0.00051286" iyz="1.961E-05" izz="3.4951E-05"/>
    </inertial>
    <visual>
      <origin rpy="0 0 0" xyz="0 0 0"/>
      <geometry>
        <mesh filename="package://sw_v3_description/meshes/assem4.STL"/>
      </geometry>
      <material name="grey"/>
    </visual>
    <collision>
      <origin rpy="0 0 0" xyz="0 0 0"/>
      <geometry>
        <mesh filename="package://sw_v3_description/meshes/assem4.STL"/>
      </geometry>
    </collision>
  </link>
  <!-- link4 -->
  <joint name="joint4" type="revolute">
    <origin rpy="-0.22802 0.12977 -0.01488" xyz="-2.5882E-05 -4.4829E-05 0.079795"/>
    <parent link="link3"/>
    <child link="link4"/>
    <axis xyz="0 0 1"/>
    <limit effort="1" lower="-3.1415" upper="3.1415" velocity="1.57079632679"/>
  </joint>
  <link name="link4">
    <inertial>
      <origin rpy="0 0 0" xyz="0.0050589 0.0088202 0.10635"/>
      <mass value="1.3274"/>
      <inertia ixx="0.00043296" ixy="-9.8408E-05" ixz="-0.00010411" iyy="0.00031409" iyz="-0.00018417" izz="0.00023001"/>
    </inertial>
    <visual>
      <origin rpy="0 0 0" xyz="0 0 0"/>
      <geometry>
        <mesh filename="package://sw_v3_description/meshes/assem5.STL"/>
      </geometry>
      <material name="grey"/>
    </visual>
    <collision>
      <origin rpy="0 0 0" xyz="0 0 0"/>
      <geometry>
        <mesh filename="package://sw_v3_description/meshes/assem5.STL"/>
      </geometry>
    </collision>
  </link>
  <!-- disk on top -->
  <joint name="joint5" type="revolute">
    <origin rpy="-0.023463 0.26077 -2.1852" xyz="-0.013401 -0.023212 0.10003"/>
    <parent link="link4"/>
    <child link="link5"/>
    <axis xyz="0 0 1"/>
    <limit effort="1" lower="-3.1415" upper="3.1415" velocity="1.57079632679"/>
  </joint>
  <link name="link5">
    <inertial>
      <origin rpy="0 0 0" xyz="-0.000166395896643769 -9.98506317533727E-06 0.0148981151365234"/>
      <mass value="0.697095422165826"/>
      <inertia ixx="7.37932900573311E-05" ixy="-2.63401730973886E-09" ixz="-1.38017673687992E-06" iyy="7.38370265272606E-05" iyz="-8.28214648849329E-08" izz="4.40525934610572E-08"/>
    </inertial>
    <visual>
      <origin rpy="0 0 0" xyz="0 0 0"/>
      <geometry>
        <mesh filename="package://sw_v3_description/meshes/assem6.STL"/>
      </geometry>
      <material name="grey"/>
    </visual>
    <collision>
      <origin rpy="0 0 0" xyz="0 0 0"/>
      <geometry>
        <mesh filename="package://sw_v3_description/meshes/assem6.STL"/>
      </geometry>
    </collision>
  </link>
  <!-- laser_block -->
  <joint name="joint6" type="fixed">
    <origin rpy="0 0 0" xyz="0 0 0.031"/>
    <parent link="link5"/>
    <child link="link6"/>
  </joint>
  <link name="link6">
    <inertial>
      <origin rpy="0 0 0" xyz="0 0 0.01"/>
      <mass value="0.02"/>
      <inertia ixx="1.33333333333e-06" ixy="0.0" ixz="0.0" iyy="1.33333333333e-06" iyz="0.0" izz="1.33333333333e-06"/>
    </inertial>
    <visual>
      <origin rpy="0 0 0" xyz="0 0 0.01"/>
      <geometry>
        <box size="0.02 0.02 0.02"/>
      </geometry>
      <material name="black"/>
    </visual>
    <collision>
      <origin rpy="0 0 0" xyz="0 0 0.01"/>
      <geometry>
        <box size="0.02 0.02 0.02"/>
      </geometry>
    </collision>
  </link>
  <transmission name="tran1">
    <type>transmission_interface/SimpleTransmission</type>
    <joint name="joint1">
      <hardwareInterface>hardware_interface/EffortJointInterface</hardwareInterface>
    </joint>
    <actuator name="motor1">
      <hardwareInterface>hardware_interface/EffortJointInterface</hardwareInterface>
      <mechanicalReduction>1</mechanicalReduction>
    </actuator>
  </transmission>
  <transmission name="tran2">
    <type>transmission_interface/SimpleTransmission</type>
    <joint name="joint2">
      <hardwareInterface>hardware_interface/EffortJointInterface</hardwareInterface>
    </joint>
    <actuator name="motor2">
      <hardwareInterface>hardware_interface/EffortJointInterface</hardwareInterface>
      <mechanicalReduction>1</mechanicalReduction>
    </actuator>
  </transmission>
  <transmission name="tran3">
    <type>transmission_interface/SimpleTransmission</type>
    <joint name="joint3">
      <hardwareInterface>hardware_interface/EffortJointInterface</hardwareInterface>
    </joint>
    <actuator name="motor3">
      <hardwareInterface>hardware_interface/EffortJointInterface</hardwareInterface>
      <mechanicalReduction>1</mechanicalReduction>
    </actuator>
  </transmission>
  <transmission name="tran4">
    <type>transmission_interface/SimpleTransmission</type>
    <joint name="joint4">
      <hardwareInterface>hardware_interface/EffortJointInterface</hardwareInterface>
    </joint>
    <actuator name="motor4">
      <hardwareInterface>hardware_interface/EffortJointInterface</hardwareInterface>
      <mechanicalReduction>1</mechanicalReduction>
    </actuator>
  </transmission>
  <transmission name="tran5">
    <type>transmission_interface/SimpleTransmission</type>
    <joint name="joint5">
      <hardwareInterface>hardware_interface/EffortJointInterface</hardwareInterface>
    </joint>
    <actuator name="motor5">
      <hardwareInterface>hardware_interface/EffortJointInterface</hardwareInterface>
      <mechanicalReduction>1</mechanicalReduction>
    </actuator>
  </transmission>
</robot>
